<?xml version="1.0"?>

<sdf version="1.4">
	<model name="blackline">
<!-- link frame -->
		<link name="frame_top">
			<pose> 0 0 0.78 </pose>
			<visual name="visual">
				<geometry>
					<box>
						<size> 0.92 0.92 0.02 </size>
					</box>
				</geometry>
				<material>
					<rgba>0 0 0 1</rgba>
				</material>
			</visual>
			<collision name="collision">
				<geometry>
					<box>
						<size> 0.92 0.92 0.02 </size>
					</box>
				</geometry>
			</collision>
		</link>

		<link name="frame_pole">
			<pose> 0 0 0.53 </pose>
			<visual name="visual">
				<geometry>
					<cylinder>
						<radius> 0.1 </radius>
						<length> 0.74 </length>
					</cylinder>
				</geometry>
			</visual>
			<collision name="collision">
				<geometry>
					<cylinder>
						<radius> 0.1 </radius>
						<length> 0.74 </length>
					</cylinder>
				</geometry>
			</collision>
		</link>

		<link name="frame_bot">
			<pose> 0 0 0.16 </pose>
			<visual name="visual">
				<geometry>
					<box>
						<size> 0.92 0.96 0.02 </size>
					</box>
				</geometry>
			</visual>
			<collision name="collision">
				<geometry>
					<box>
						<size> 0.92 0.96 0.02 </size>
					</box>
				</geometry>
			</collision>
		</link>

		<link name="frame_left">
			<pose> -0.47 0 0.44 </pose>
			<visual name="visual">
				<geometry>
					<box>
						<size> 0.02 0.96 0.7 </size>
					</box>
				</geometry>
			</visual>
			<collision name="collision">
				<geometry>
					<box>
						<size> 0.02 0.96 0.7 </size>
					</box>
				</geometry>
			</collision>
		</link>

		<link name="frame_right">
			<pose> 0.47 0 0.44 </pose>
			<visual name="visual">
				<geometry>
					<box>
						<size> 0.02 0.96 0.7 </size>
					</box>
				</geometry>
			</visual>
			<collision name="collision">
				<geometry>
					<box>
						<size> 0.02 0.96 0.7 </size>
					</box>
				</geometry>
			</collision>
		</link>

		<link name="frame_front">
			<pose> 0 0.47 0.49 </pose>
			<visual name="visual">
				<geometry>
					<box>
						<size> 0.92 0.02 0.6 </size>
					</box>
				</geometry>
			</visual>
			<collision name="collision">
				<geometry>
					<box>
						<size> 0.92 0.02 0.6 </size>
					</box>
				</geometry>
			</collision>
		</link>

		<link name="frame_rear">
			<pose> 0 -0.47 0.49 </pose>
			<visual name="visual">
				<geometry>
					<box>
						<size> 0.92 0.02 0.6 </size>
					</box>
				</geometry>
			</visual>
			<collision name="collision">
				<geometry>
					<box>
						<size> 0.92 0.02 0.6 </size>
					</box>
				</geometry>
			</collision>
		</link>

<!-- joint frame -->

		<joint name="frame_lift" type="prismatic">
			<parent>frame_top</parent>
			<child>frame_pole</child>
			<axis>
				<xyz> 0 0 1 </xyz>
				<dynamics>
					<friction> 2000 </friction>
					<damping> 1000 </damping>
				</dynamics>
				<limit>
					<upper> 0.0 </upper>
					<lower> -0.12 </lower>
				</limit>
			</axis>
		</joint>

		<joint name="frame_joint0" type="fixed">
			<parent>frame_pole</parent>
			<child>frame_bot</child>
		</joint>

		<joint name="frame_joint1" type="fixed">
			<parent>frame_top</parent>
			<child>frame_left</child>
		</joint>

		<joint name="frame_joint2" type="fixed">
			<parent>frame_top</parent>
			<child>frame_right</child>
		</joint>

		<joint name="frame_joint3" type="fixed">
			<parent>frame_top</parent>
			<child>frame_front</child>
		</joint>

		<joint name="frame_joint4" type="fixed">
			<parent>frame_top</parent>
			<child>frame_rear</child>
		</joint>

<!-- link wheel x -->
		<link name="wheel_x_lf">
			<pose> 0.35 0.5 0.16 1.5707 0 0 </pose>
			<visual name="visual">
				<geometry>
					<cylinder>
						<radius> 0.1 </radius>
						<length> 0.04 </length>
					</cylinder>
				</geometry>
			</visual>
			<collision name ="collision">
				<geometry>
					<cylinder>
						<radius> 0.1 </radius>
						<length> 0.04 </length>
					</cylinder>
				</geometry>
			</collision>
		</link>

		<link name="wheel_x_lr">
			<pose> -0.35 0.5 0.16 1.5707 0 0 </pose>
			<visual name="visual">
				<geometry>
					<cylinder>
						<radius> 0.1 </radius>
						<length> 0.04 </length>
					</cylinder>
				</geometry>
			</visual>
			<collision name ="collision">
				<geometry>
					<cylinder>
						<radius> 0.1 </radius>
						<length> 0.04 </length>
					</cylinder>
				</geometry>
			</collision>
		</link>

		<link name="wheel_x_rf">
			<pose> 0.35 -0.5 0.16 1.5707 0 0 </pose>
			<visual name="visual">
				<geometry>
					<cylinder>
						<radius> 0.1 </radius>
						<length> 0.04 </length>
					</cylinder>
				</geometry>
			</visual>
			<collision name ="collision">
				<geometry>
					<cylinder>
						<radius> 0.1 </radius>
						<length> 0.04 </length>
					</cylinder>
				</geometry>
			</collision>
		</link>

		<link name="wheel_x_rr">
			<pose> -0.35 -0.5 0.16 1.5707 0 0 </pose>
			<visual name="visual">
				<geometry>
					<cylinder>
						<radius> 0.1 </radius>
						<length> 0.04 </length>
					</cylinder>
				</geometry>
			</visual>
			<collision name ="collision">
				<geometry>
					<cylinder>
						<radius> 0.1 </radius>
						<length> 0.04 </length>
					</cylinder>
				</geometry>
			</collision>
		</link>

<!-- joint wheel x -->
		<joint name="joint_x_lf" type="revolute">
			<parent>frame_bot</parent>
			<child>wheel_x_lf</child>
			<axis>
				<xyz> 0 1 0 </xyz>
			</axis>
			<pose> 0 0 0 </pose>
		</joint>
		<joint name="joint_x_lr" type="revolute">
			<parent>frame_bot</parent>
			<child>wheel_x_lr</child>
			<axis>
				<xyz> 0 1 0 </xyz>
			</axis>
			<pose> 0 0 0 </pose>
		</joint>
		<joint name="joint_x_rf" type="revolute">
			<parent>frame_bot</parent>
			<child>wheel_x_rf</child>
			<axis>
				<xyz> 0 1 0 </xyz>
			</axis>
			<pose> 0 0 0 </pose>
		</joint>
		<joint name="joint_x_rr" type="revolute">
			<parent>frame_bot</parent>
			<child>wheel_x_rr</child>
			<axis>
				<xyz> 0 1 0 </xyz>
			</axis>
			<pose> 0 0 0 </pose>
		</joint>

<!-- frame wheel y -->
		<link name="wheel_y_lf">
			<pose> -0.5 0.35 0.1 0 1.57070 0 </pose>
			<visual name="visual">
				<geometry>
					<cylinder>
						<radius> 0.1 </radius>
						<length> 0.04 </length>
					</cylinder>
				</geometry>
			</visual>
			<collision name="collision">
				<geometry>
					<cylinder>
						<radius> 0.1 </radius>
						<length> 0.04 </length>
					</cylinder>
				</geometry>
			</collision>
		</link>

		<link name="wheel_y_lr">
			<pose> -0.5 -0.35 0.1 0 1.57070 0 </pose>
			<visual name="visual">
				<geometry>
					<cylinder>
						<radius> 0.1 </radius>
						<length> 0.04 </length>
					</cylinder>
				</geometry>
			</visual>
			<collision name="collision">
				<geometry>
					<cylinder>
						<radius> 0.1 </radius>
						<length> 0.04 </length>
					</cylinder>
				</geometry>
			</collision>
		</link>

		<link name="wheel_y_rf">
			<pose> 0.5 0.35 0.1 0 1.57070 0 </pose>
			<visual name="visual">
				<geometry>
					<cylinder>
						<radius> 0.1 </radius>
						<length> 0.04 </length>
					</cylinder>
				</geometry>
			</visual>
			<collision name="collision">
				<geometry>
					<cylinder>
						<radius> 0.1 </radius>
						<length> 0.04 </length>
					</cylinder>
				</geometry>
			</collision>
		</link>

		<link name="wheel_y_rr">
			<pose> 0.5 -0.35 0.1 0 1.57070 0 </pose>
			<visual name="visual">
				<geometry>
					<cylinder>
						<radius> 0.1 </radius>
						<length> 0.04 </length>
					</cylinder>
				</geometry>
			</visual>
			<collision name="collision">
				<geometry>
					<cylinder>
						<radius> 0.1 </radius>
						<length> 0.04 </length>
					</cylinder>
				</geometry>
			</collision>
		</link>

<!-- joint wheel y -->
		<joint name="joint_y_lf" type="revolute">
			<parent>frame_top</parent>
			<child>wheel_y_lf</child>
			<axis>
				<xyz> -1 0 0 </xyz>
			</axis>
			<pose> 0 0 0 </pose>
		</joint>
		<joint name="joint_y_lr" type="revolute">
			<parent>frame_top</parent>
			<child>wheel_y_lr</child>
			<axis>
				<xyz> -1 0 0 </xyz>
			</axis>
			<pose> 0 0 0 </pose>
		</joint>
		<joint name="joint_y_rf" type="revolute">
			<parent>frame_top</parent>
			<child>wheel_y_rf</child>
			<axis>
				<xyz> -1 0 0 </xyz>
			</axis>
			<pose> 0 0 0 </pose>
		</joint>
		<joint name="joint_y_rr" type="revolute">
			<parent>frame_top</parent>
			<child>wheel_y_rr</child>
			<axis>
				<xyz> -1 0 0 </xyz>
			</axis>
			<pose> 0 0 0 </pose>
		</joint>

<!-- plugin -->

		<plugin name="planar_control" filename="libgazebo_ros_planar_move.so">
			<ros>
				<namespace>/demo</namespace>
				<argument>cmd_vel:=cmd_vel</argument>
				<argument>odom:=odom</argument>
			</ros>

			<update_rate>100</update_rate>
			<publish_rate>10</publish_rate>

			<!-- output -->
			<publish_odom>true</publish_odom>
			<publish_odom_tf>true</publish_odom_tf>

			<odometry_frame>odom_demo</odometry_frame>
			<robot_base_frame>naim_frame</robot_base_frame>

			<covariance_x>0.0001</covariance_x>
			<covariance_y>0.0001</covariance_y>
			<covariance_yaw>0.01</covariance_yaw>
		</plugin>

		<!-- <plugin name="lift_control" filename="libgazebo_ros_joint_pose_trajectory.so">
			<ros>
				<argument>set_joint_trajectory:=joint_control</argument>
			</ros>
			<update_rate>100</update_rate>
		</plugin> -->

		<!-- <plugin name='drive_plugin_x' filename='libgazebo_ros_diff_drive.so'>
			<ros>
				<namespace>/blackline</namespace>
				<argument>cmd_vel:=wheel_control_x</argument>
				<argument>odom:=odometry</argument>
			</ros>

			<num_wheel_pairs>2</num_wheel_pairs>

			<left_joint>joint_x_lf</left_joint>
			<right_joint>joint_x_rf</right_joint>
			<left_joint>joint_x_lr</left_joint>
			<right_joint>joint_x_rr</right_joint>

			<wheel_separation>1.0</wheel_separation>
			<wheel_separation>1.0</wheel_separation>

			<wheel_diameter>0.1</wheel_diameter>
			<wheel_diameter>0.1</wheel_diameter>

			<max_wheel_torque>20</max_wheel_torque>
			<max_wheel_acceleration>1.0</max_wheel_acceleration>

			<publish_odom>true</publish_odom>
			<publish_odom_tf>true</publish_odom_tf>
			<publish_wheel_tf>true</publish_wheel_tf>

			<odometry_frame>odom_demo</odometry_frame>
			<robot_base_frame>frame_top</robot_base_frame>
		</plugin> -->

		<!-- <plugin name='drive_plugin_y' filename='libgazebo_ros_diff_drive.so'>
			<ros>
				<argument>cmd_vel:=wheel_control_y</argument>
			</ros>

			<num_wheel_pairs>2</num_wheel_pairs>

			<left_joint>joint_y_lf</left_joint>
			<right_joint>joint_y_rf</right_joint>
			<left_joint>joint_y_lr</left_joint>
			<right_joint>joint_y_rr</right_joint>

			<wheel_separation>1.0</wheel_separation>
			<wheel_separation>1.0</wheel_separation>

			<wheel_diameter>0.1</wheel_diameter>
			<wheel_diameter>0.1</wheel_diameter>

			<max_wheel_torque>20</max_wheel_torque>
			<max_wheel_acceleration>1.0</max_wheel_acceleration>

			<publish_odom>false</publish_odom>
			<publish_odom_tf>false</publish_odom_tf>
			<publish_wheel_tf>true</publish_wheel_tf>

			<odometry_frame>odom_demo</odometry_frame>
			<robot_base_frame>frame_top</robot_base_frame>
		</plugin> -->

<!-- end of file -->
	</model>
</sdf>